2024-08-02 19:58:41,437 - ERROR - root - userManager.py:20 - An error occurred while loading users. Try restarting the program because some functionalities won't work: User.__init__() got an unexpected keyword argument 'borrowed_books'
2024-08-02 19:58:41,437 - ERROR - root - userManager.py:20 - An error occurred while loading users. Try restarting the program because some functionalities won't work: User.__init__() got an unexpected keyword argument 'borrowed_books'
2024-08-02 20:03:19,972 - ERROR - root - bookManager.py:222 - An error occurred while deleting book: '288'
2024-08-02 20:03:19,972 - ERROR - root - bookManager.py:222 - An error occurred while deleting book: '288'
2024-08-02 20:05:39,328 - ERROR - root - bookManager.py:222 - An error occurred while deleting book: '288'
2024-08-02 20:05:39,328 - ERROR - root - bookManager.py:222 - An error occurred while deleting book: '288'
2024-08-02 20:07:56,726 - ERROR - root - bookManager.py:212 - Book not found: '288'
2024-08-02 20:07:56,726 - ERROR - root - bookManager.py:212 - Book not found: '288'
2024-08-02 20:31:38,351 - ERROR - root - userManager.py:135 - An error occurred while deleting user: 'int' object has no attribute 'pop'
2024-08-02 20:31:38,351 - ERROR - root - userManager.py:135 - An error occurred while deleting user: 'int' object has no attribute 'pop'
2024-08-02 20:33:16,363 - ERROR - root - userManager.py:135 - An error occurred while deleting user: 'User' object has no attribute 'user'
2024-08-02 20:33:16,363 - ERROR - root - userManager.py:135 - An error occurred while deleting user: 'User' object has no attribute 'user'
2024-08-02 20:34:57,986 - ERROR - root - userManager.py:137 - An error occurred while deleting user: 'User' object has no attribute 'user'
2024-08-02 20:34:57,986 - ERROR - root - userManager.py:137 - An error occurred while deleting user: 'User' object has no attribute 'user'
2024-08-02 20:35:57,508 - ERROR - root - userManager.py:138 - An error occurred while deleting user: 'User' object has no attribute 'user'
2024-08-02 20:35:57,508 - ERROR - root - userManager.py:138 - An error occurred while deleting user: 'User' object has no attribute 'user'
2024-08-02 20:36:12,678 - ERROR - root - userManager.py:141 - An error occurred while deleting user: 'User' object has no attribute 'user'
2024-08-02 20:36:12,678 - ERROR - root - userManager.py:141 - An error occurred while deleting user: 'User' object has no attribute 'user'
